Workbook

Sheet WB
A1: Vessel Space Utilization Report - | H1: Selection: Source Bayplan, Actual Booking & CBF
A2: Service Lane : CGX/0005 | D2: EXPRESS BERLIN / XPBL2625WE | AA2: WB ALLOCATION : | AC2: 0 | AD2: TEUS, | AG2: MT, | AH2: 0 | AI2: RF PLUGS
A3: POD | D3: CNTAO | F3: CNSHA | H3: CNNGB | J3: CNSHK | L3: CNNSA | N3: MYPKG | P3: INMUN | R3: AEKLF | T3: OMSOH | V3: PKKHI | X3: CNTAO | AA3: TOTAL | AC3: TTL | AD3: ROB (TEUS) | AF3: UTILISATION | AH3: AVL | AJ3: RF Plug
A4: ETA | D4: 06/29 | F4: 07/03 | H4: 07/04 | J4: 07/07 | L4: 07/08 | N4: 07/13 | P4: SKIP | R4: 07/24 | T4: 07/27 | V4: 08/01 | X4: 08/16
A5: POL | D5: 20' | E5: 40' | F5: 20' | G5: 40' | H5: 20' | I5: 40' | J5: 20' | K5: 40' | L5: 20' | M5: 40' | N5: 20' | O5: 40' | P5: 20' | Q5: 40' | R5: 20' | S5: 40' | T5: 20' | U5: 40' | V5: 20' | W5: 40' | X5: 20' | Y5: 40' | AA5: 20' | AB5: 40' | AC5: TEUS | AD5: (All) | AE5: (LD) | AF5: (All) | AG5: (LD) | AH5: TEUs | AI5: Weight
A6: ROB | C6: LILIAN | AA6: =D6+F6+H6+J6+L6+N6+P6+R6+T6+V6+X6 -> 0 | AB6: =E6+G6+I6+K6+M6+O6+Q6+S6+U6+W6+Y6 -> 0 | AC6: =AA6+AB6*2 -> 0 | AD6: =0+AC6+AC7+AC8+AC9+AC10+AC11-(0) -> 0 | AE6: =0+AC6+AC7+AC8+AC9+AC10-((0)-(0)) -> 0 | AF6: =IF($AC$2>0,AD6/$AC$2,0) -> 0 | AG6: =IF($AC$2>0,AE6/$AC$2,0) -> 0
C7: SUL | AA7: =D7+F7+H7+J7+L7+N7+P7+R7+T7+V7+X7 -> 0 | AB7: =E7+G7+I7+K7+M7+O7+Q7+S7+U7+W7+Y7 -> 0 | AC7: =AA7+AB7*2 -> 0
C8: T/S | AA8: =D8+F8+H8+J8+L8+N8+P8+R8+T8+V8+X8 -> 0 | AB8: =E8+G8+I8+K8+M8+O8+Q8+S8+U8+W8+Y8 -> 0 | AC8: =AA8+AB8*2 -> 0
C9: SOC | AA9: =D9+F9+H9+J9+L9+N9+P9+R9+T9+V9+X9 -> 0 | AB9: =E9+G9+I9+K9+M9+O9+Q9+S9+U9+W9+Y9 -> 0 | AC9: =AA9+AB9*2 -> 0
C10: RF | AA10: =D10+F10+H10+J10+L10+N10+P10+R10+T10+V10+X10 -> 0 | AB10: =E10+G10+I10+K10+M10+O10+Q10+S10+U10+W10+Y10 -> 0 | AC10: =AA10+AB10*2 -> 0 | AJ10: =$AH$2-(AA10+AB10) -> 0
C11: MT | AA11: =D11+F11+H11+J11+L11+N11+P11+R11+T11+V11+X11 -> 0 | AB11: =E11+G11+I11+K11+M11+O11+Q11+S11+U11+W11+Y11 -> 0 | AC11: =AA11+AB11*2 -> 0
C12: Weight | AA12: =D12+F12+H12+J12+L12+N12+P12+R12+T12+V12+X12 -> 0 | AD12: =0+AA12-(0) -> 0 | AE12: =AD12-(AD6-AE6)*2 -> 0 | AF12: =IF($AF$2>0,AD12/$AF$2,0) -> 0 | AG12: =IF($AF$2>0,AE12/$AF$2,0) -> 0 | AI12: =$AF$2-AD12 -> 0
C13: TTL | D13: =D6+D7+D8+D9+D10+D11 -> 0 | E13: =E6+E7+E8+E9+E10+E11 -> 0 | F13: =F6+F7+F8+F9+F10+F11 -> 0 | G13: =G6+G7+G8+G9+G10+G11 -> 0 | H13: =H6+H7+H8+H9+H10+H11 -> 0 | I13: =I6+I7+I8+I9+I10+I11 -> 0 | J13: =J6+J7+J8+J9+J10+J11 -> 0 | K13: =K6+K7+K8+K9+K10+K11 -> 0 | ... Y13: =Y6+Y7+Y8+Y9+Y10+Y11 -> 0 | AA13: =AA6+AA7+AA8+AA9+AA10+AA11 -> 0 | AB13: =AB6+AB7+AB8+AB9+AB10+AB11 -> 0 | AC13: =AC6+AC7+AC8+AC9+AC10+AC11 -> 0 | AH13: =$AC$2-AD6 -> 0
A14: CNTAO | C14: LILIAN | AA14: =D14+F14+H14+J14+L14+N14+P14+R14+T14+V14+X14 -> 0 | AB14: =E14+G14+I14+K14+M14+O14+Q14+S14+U14+W14+Y14 -> 0 | AC14: =AA14+AB14*2 -> 0 | AD14: =AD6+AC14+AC15+AC16+AC17+AC18+AC19-(D102) -> 0 | AE14: =AE6+AC14+AC15+AC16+AC17+AC18-((D102)-(D99+E99*2)) -> 0 | AF14: =IF($AC$2>0,AD14/$AC$2,0) -> 0 | AG14: =IF($AC$2>0,AE14/$AC$2,0) -> 0
C15: SUL | AA15: =D15+F15+H15+J15+L15+N15+P15+R15+T15+V15+X15 -> 0 | AB15: =E15+G15+I15+K15+M15+O15+Q15+S15+U15+W15+Y15 -> 0 | AC15: =AA15+AB15*2 -> 0
C16: T/S | AA16: =D16+F16+H16+J16+L16+N16+P16+R16+T16+V16+X16 -> 0 | AB16: =E16+G16+I16+K16+M16+O16+Q16+S16+U16+W16+Y16 -> 0 | AC16: =AA16+AB16*2 -> 0
C17: SOC | AA17: =D17+F17+H17+J17+L17+N17+P17+R17+T17+V17+X17 -> 0 | AB17: =E17+G17+I17+K17+M17+O17+Q17+S17+U17+W17+Y17 -> 0 | AC17: =AA17+AB17*2 -> 0
C18: RF | AA18: =D18+F18+H18+J18+L18+N18+P18+R18+T18+V18+X18 -> 0 | AB18: =E18+G18+I18+K18+M18+O18+Q18+S18+U18+W18+Y18 -> 0 | AC18: =AA18+AB18*2 -> 0 | AJ18: =AJ10-(AA18+AB18)+(D98+E98) -> 0
A19: ETB | B19: 06/28 | C19: MT | AA19: =D19+F19+H19+J19+L19+N19+P19+R19+T19+V19+X19 -> 0 | AB19: =E19+G19+I19+K19+M19+O19+Q19+S19+U19+W19+Y19 -> 0 | AC19: =AA19+AB19*2 -> 0
A20: ETD | B20: 06/29 | C20: Weight | AA20: =D20+F20+H20+J20+L20+N20+P20+R20+T20+V20+X20 -> 0 | AD20: =AD12+AA20-(D103) -> 0 | AE20: =AD20-(AD14-AE14)*2 -> 0 | AF20: =IF($AF$2>0,AD20/$AF$2,0) -> 0 | AG20: =IF($AF$2>0,AE20/$AF$2,0) -> 0 | AI20: =$AF$2-AD20 -> 0
C21: TTL | D21: =D14+D15+D16+D17+D18+D19 -> 0 | E21: =E14+E15+E16+E17+E18+E19 -> 0 | F21: =F14+F15+F16+F17+F18+F19 -> 0 | G21: =G14+G15+G16+G17+G18+G19 -> 0 | H21: =H14+H15+H16+H17+H18+H19 -> 0 | I21: =I14+I15+I16+I17+I18+I19 -> 0 | J21: =J14+J15+J16+J17+J18+J19 -> 0 | K21: =K14+K15+K16+K17+K18+K19 -> 0 | ... Y21: =Y14+Y15+Y16+Y17+Y18+Y19 -> 0 | AA21: =AA14+AA15+AA16+AA17+AA18+AA19 -> 0 | AB21: =AB14+AB15+AB16+AB17+AB18+AB19 -> 0 | AC21: =AC14+AC15+AC16+AC17+AC18+AC19 -> 0 | AH21: =$AC$2-AD14 -> 0
A22: CNSHA | C22: LILIAN | AA22: =D22+F22+H22+J22+L22+N22+P22+R22+T22+V22+X22 -> 0 | AB22: =E22+G22+I22+K22+M22+O22+Q22+S22+U22+W22+Y22 -> 0 | AC22: =AA22+AB22*2 -> 0 | AD22: =AD14+AC22+AC23+AC24+AC25+AC26+AC27-(F102) -> 0 | AE22: =AE14+AC22+AC23+AC24+AC25+AC26-((F102)-(F99+G99*2)) -> 0 | AF22: =IF($AC$2>0,AD22/$AC$2,0) -> 0 | AG22: =IF($AC$2>0,AE22/$AC$2,0) -> 0
C23: SUL | AA23: =D23+F23+H23+J23+L23+N23+P23+R23+T23+V23+X23 -> 0 | AB23: =E23+G23+I23+K23+M23+O23+Q23+S23+U23+W23+Y23 -> 0 | AC23: =AA23+AB23*2 -> 0
C24: T/S | AA24: =D24+F24+H24+J24+L24+N24+P24+R24+T24+V24+X24 -> 0 | AB24: =E24+G24+I24+K24+M24+O24+Q24+S24+U24+W24+Y24 -> 0 | AC24: =AA24+AB24*2 -> 0
C25: SOC | AA25: =D25+F25+H25+J25+L25+N25+P25+R25+T25+V25+X25 -> 0 | AB25: =E25+G25+I25+K25+M25+O25+Q25+S25+U25+W25+Y25 -> 0 | AC25: =AA25+AB25*2 -> 0
C26: RF | AA26: =D26+F26+H26+J26+L26+N26+P26+R26+T26+V26+X26 -> 0 | AB26: =E26+G26+I26+K26+M26+O26+Q26+S26+U26+W26+Y26 -> 0 | AC26: =AA26+AB26*2 -> 0 | AJ26: =AJ18-(AA26+AB26)+(F98+G98) -> 0
A27: ETB | B27: 07/02 | C27: MT | AA27: =D27+F27+H27+J27+L27+N27+P27+R27+T27+V27+X27 -> 0 | AB27: =E27+G27+I27+K27+M27+O27+Q27+S27+U27+W27+Y27 -> 0 | AC27: =AA27+AB27*2 -> 0
A28: ETD | B28: 07/03 | C28: Weight | AA28: =D28+F28+H28+J28+L28+N28+P28+R28+T28+V28+X28 -> 0 | AD28: =AD20+AA28-(F103) -> 0 | AE28: =AD28-(AD22-AE22)*2 -> 0 | AF28: =IF($AF$2>0,AD28/$AF$2,0) -> 0 | AG28: =IF($AF$2>0,AE28/$AF$2,0) -> 0 | AI28: =$AF$2-AD28 -> 0
C29: TTL | D29: =D22+D23+D24+D25+D26+D27 -> 0 | E29: =E22+E23+E24+E25+E26+E27 -> 0 | F29: =F22+F23+F24+F25+F26+F27 -> 0 | G29: =G22+G23+G24+G25+G26+G27 -> 0 | H29: =H22+H23+H24+H25+H26+H27 -> 0 | I29: =I22+I23+I24+I25+I26+I27 -> 0 | J29: =J22+J23+J24+J25+J26+J27 -> 0 | K29: =K22+K23+K24+K25+K26+K27 -> 0 | ... Y29: =Y22+Y23+Y24+Y25+Y26+Y27 -> 0 | AA29: =AA22+AA23+AA24+AA25+AA26+AA27 -> 0 | AB29: =AB22+AB23+AB24+AB25+AB26+AB27 -> 0 | AC29: =AC22+AC23+AC24+AC25+AC26+AC27 -> 0 | AH29: =$AC$2-AD22 -> 0
A30: CNNGB | C30: LILIAN | AA30: =D30+F30+H30+J30+L30+N30+P30+R30+T30+V30+X30 -> 0 | AB30: =E30+G30+I30+K30+M30+O30+Q30+S30+U30+W30+Y30 -> 0 | AC30: =AA30+AB30*2 -> 0 | AD30: =AD22+AC30+AC31+AC32+AC33+AC34+AC35-(H102) -> 0 | AE30: =AE22+AC30+AC31+AC32+AC33+AC34-((H102)-(H99+I99*2)) -> 0 | AF30: =IF($AC$2>0,AD30/$AC$2,0) -> 0 | AG30: =IF($AC$2>0,AE30/$AC$2,0) -> 0
C31: SUL | AA31: =D31+F31+H31+J31+L31+N31+P31+R31+T31+V31+X31 -> 0 | AB31: =E31+G31+I31+K31+M31+O31+Q31+S31+U31+W31+Y31 -> 0 | AC31: =AA31+AB31*2 -> 0
C32: T/S | AA32: =D32+F32+H32+J32+L32+N32+P32+R32+T32+V32+X32 -> 0 | AB32: =E32+G32+I32+K32+M32+O32+Q32+S32+U32+W32+Y32 -> 0 | AC32: =AA32+AB32*2 -> 0
C33: SOC | AA33: =D33+F33+H33+J33+L33+N33+P33+R33+T33+V33+X33 -> 0 | AB33: =E33+G33+I33+K33+M33+O33+Q33+S33+U33+W33+Y33 -> 0 | AC33: =AA33+AB33*2 -> 0
C34: RF | AA34: =D34+F34+H34+J34+L34+N34+P34+R34+T34+V34+X34 -> 0 | AB34: =E34+G34+I34+K34+M34+O34+Q34+S34+U34+W34+Y34 -> 0 | AC34: =AA34+AB34*2 -> 0 | AJ34: =AJ26-(AA34+AB34)+(H98+I98) -> 0
A35: ETB | B35: 07/04 | C35: MT | AA35: =D35+F35+H35+J35+L35+N35+P35+R35+T35+V35+X35 -> 0 | AB35: =E35+G35+I35+K35+M35+O35+Q35+S35+U35+W35+Y35 -> 0 | AC35: =AA35+AB35*2 -> 0
A36: ETD | B36: 07/04 | C36: Weight | AA36: =D36+F36+H36+J36+L36+N36+P36+R36+T36+V36+X36 -> 0 | AD36: =AD28+AA36-(H103) -> 0 | AE36: =AD36-(AD30-AE30)*2 -> 0 | AF36: =IF($AF$2>0,AD36/$AF$2,0) -> 0 | AG36: =IF($AF$2>0,AE36/$AF$2,0) -> 0 | AI36: =$AF$2-AD36 -> 0
C37: TTL | D37: =D30+D31+D32+D33+D34+D35 -> 0 | E37: =E30+E31+E32+E33+E34+E35 -> 0 | F37: =F30+F31+F32+F33+F34+F35 -> 0 | G37: =G30+G31+G32+G33+G34+G35 -> 0 | H37: =H30+H31+H32+H33+H34+H35 -> 0 | I37: =I30+I31+I32+I33+I34+I35 -> 0 | J37: =J30+J31+J32+J33+J34+J35 -> 0 | K37: =K30+K31+K32+K33+K34+K35 -> 0 | ... Y37: =Y30+Y31+Y32+Y33+Y34+Y35 -> 0 | AA37: =AA30+AA31+AA32+AA33+AA34+AA35 -> 0 | AB37: =AB30+AB31+AB32+AB33+AB34+AB35 -> 0 | AC37: =AC30+AC31+AC32+AC33+AC34+AC35 -> 0 | AH37: =$AC$2-AD30 -> 0
A38: CNSHK | C38: LILIAN | AA38: =D38+F38+H38+J38+L38+N38+P38+R38+T38+V38+X38 -> 0 | AB38: =E38+G38+I38+K38+M38+O38+Q38+S38+U38+W38+Y38 -> 0 | AC38: =AA38+AB38*2 -> 0 | AD38: =AD30+AC38+AC39+AC40+AC41+AC42+AC43-(J102) -> 0 | AE38: =AE30+AC38+AC39+AC40+AC41+AC42-((J102)-(J99+K99*2)) -> 0 | AF38: =IF($AC$2>0,AD38/$AC$2,0) -> 0 | AG38: =IF($AC$2>0,AE38/$AC$2,0) -> 0
C39: SUL | AA39: =D39+F39+H39+J39+L39+N39+P39+R39+T39+V39+X39 -> 0 | AB39: =E39+G39+I39+K39+M39+O39+Q39+S39+U39+W39+Y39 -> 0 | AC39: =AA39+AB39*2 -> 0
C40: T/S | AA40: =D40+F40+H40+J40+L40+N40+P40+R40+T40+V40+X40 -> 0 | AB40: =E40+G40+I40+K40+M40+O40+Q40+S40+U40+W40+Y40 -> 0 | AC40: =AA40+AB40*2 -> 0
...

Sheet EB
A1: Vessel Space Utilization Report - | H1: Selection: Source Bayplan, Actual Booking & CBF
A2: =WB!A2 -> Service Lane : CGX/0005 | D2: =WB!D2 -> EXPRESS BERLIN / XPBL2625WE | AE2: EB ALLOCATION : | AG2: =WB!AC2 -> 0 | AH2: TEUS, | AJ2: =WB!AF2 -> 0 | AK2: MT, | AL2: =WB!AH2 -> 0 | AM2: RF PLUGS
A3: POD | D3: AEKLF | F3: OMSOH | H3: PKKHI | J3: CNTAO | L3: CNSHA | N3: CNNGB | P3: CNSHK | R3: CNNSA | T3: MYPKG | V3: INMUN | X3: AEKLF | Z3: OMSOH | AB3: PKKHI | AE3: TOTAL | AG3: TTL | AH3: ROB (TEUS) | AJ3: UTILISATION | AL3: AVL | AN3: RF Plug
A4: ETA | D4: 07/24 | F4: 07/27 | H4: 08/01 | J4: 08/16 | L4: 08/20 | N4: 08/21 | P4: 08/24 | R4: 08/25 | T4: 08/30 | V4: SKIP | X4: 09/10 | Z4: 09/13 | AB4: 09/18
A5: POL | D5: 20' | E5: 40' | F5: 20' | G5: 40' | H5: 20' | I5: 40' | J5: 20' | K5: 40' | L5: 20' | M5: 40' | N5: 20' | O5: 40' | P5: 20' | Q5: 40' | R5: 20' | S5: 40' | T5: 20' | U5: 40' | V5: 20' | W5: 40' | X5: 20' | Y5: 40' | Z5: 20' | AA5: 40' | AB5: 20' | AC5: 40' | AE5: 20' | AF5: 40' | AG5: TEUS | AH5: (All) | AI5: (LD) | AJ5: (All) | AK5: (LD) | AL5: TEUs | AM5: Weight
A6: ROB | C6: LILIAN | AE6: =D6+F6+H6+J6+L6+N6+P6+R6+T6+V6+X6+Z6+AB6 -> 0 | AF6: =E6+G6+I6+K6+M6+O6+Q6+S6+U6+W6+Y6+AA6+AC6 -> 0 | AG6: =AE6+AF6*2 -> 0 | AH6: =0+AG6+AG7+AG8+AG9+AG10+AG11-(0) -> 0 | AI6: =0+AG6+AG7+AG8+AG9+AG10-((0)-(0)) -> 0 | AJ6: =IF($AG$2>0,AH6/$AG$2,0) -> 0 | AK6: =IF($AG$2>0,AI6/$AG$2,0) -> 0
C7: SUL | AE7: =D7+F7+H7+J7+L7+N7+P7+R7+T7+V7+X7+Z7+AB7 -> 0 | AF7: =E7+G7+I7+K7+M7+O7+Q7+S7+U7+W7+Y7+AA7+AC7 -> 0 | AG7: =AE7+AF7*2 -> 0
C8: T/S | AE8: =D8+F8+H8+J8+L8+N8+P8+R8+T8+V8+X8+Z8+AB8 -> 0 | AF8: =E8+G8+I8+K8+M8+O8+Q8+S8+U8+W8+Y8+AA8+AC8 -> 0 | AG8: =AE8+AF8*2 -> 0
C9: SOC | AE9: =D9+F9+H9+J9+L9+N9+P9+R9+T9+V9+X9+Z9+AB9 -> 0 | AF9: =E9+G9+I9+K9+M9+O9+Q9+S9+U9+W9+Y9+AA9+AC9 -> 0 | AG9: =AE9+AF9*2 -> 0
C10: RF | AE10: =D10+F10+H10+J10+L10+N10+P10+R10+T10+V10+X10+Z10+AB10 -> 0 | AF10: =E10+G10+I10+K10+M10+O10+Q10+S10+U10+W10+Y10+AA10+AC10 -> 0 | AG10: =AE10+AF10*2 -> 0 | AN10: =$AL$2-(AE10+AF10) -> 0
C11: MT | AE11: =D11+F11+H11+J11+L11+N11+P11+R11+T11+V11+X11+Z11+AB11 -> 0 | AF11: =E11+G11+I11+K11+M11+O11+Q11+S11+U11+W11+Y11+AA11+AC11 -> 0 | AG11: =AE11+AF11*2 -> 0
C12: Weight | AE12: =D12+F12+H12+J12+L12+N12+P12+R12+T12+V12+X12+Z12+AB12 -> 0 | AH12: =0+AE12-(0) -> 0 | AI12: =AH12-(AH6-AI6)*2 -> 0 | AJ12: =IF($AJ$2>0,AH12/$AJ$2,0) -> 0 | AK12: =IF($AJ$2>0,AI12/$AJ$2,0) -> 0 | AM12: =$AJ$2-AH12 -> 0
C13: TTL | D13: =D6+D7+D8+D9+D10+D11 -> 0 | E13: =E6+E7+E8+E9+E10+E11 -> 0 | F13: =F6+F7+F8+F9+F10+F11 -> 0 | G13: =G6+G7+G8+G9+G10+G11 -> 0 | H13: =H6+H7+H8+H9+H10+H11 -> 0 | I13: =I6+I7+I8+I9+I10+I11 -> 0 | J13: =J6+J7+J8+J9+J10+J11 -> 0 | K13: =K6+K7+K8+K9+K10+K11 -> 0 | ... AC13: =AC6+AC7+AC8+AC9+AC10+AC11 -> 0 | AE13: =AE6+AE7+AE8+AE9+AE10+AE11 -> 0 | AF13: =AF6+AF7+AF8+AF9+AF10+AF11 -> 0 | AG13: =AG6+AG7+AG8+AG9+AG10+AG11 -> 0 | AL13: =$AG$2-AH6 -> 0
A14: AEKLF | C14: LILIAN | AE14: =D14+F14+H14+J14+L14+N14+P14+R14+T14+V14+X14+Z14+AB14 -> 0 | AF14: =E14+G14+I14+K14+M14+O14+Q14+S14+U14+W14+Y14+AA14+AC14 -> 0 | AG14: =AE14+AF14*2 -> 0 | AH14: =AH6+AG14+AG15+AG16+AG17+AG18+AG19-(D54) -> 0 | AI14: =AI6+AG14+AG15+AG16+AG17+AG18-((D54)-(D51+E51*2)) -> 0 | AJ14: =IF($AG$2>0,AH14/$AG$2,0) -> 0 | AK14: =IF($AG$2>0,AI14/$AG$2,0) -> 0
C15: SUL | AE15: =D15+F15+H15+J15+L15+N15+P15+R15+T15+V15+X15+Z15+AB15 -> 0 | AF15: =E15+G15+I15+K15+M15+O15+Q15+S15+U15+W15+Y15+AA15+AC15 -> 0 | AG15: =AE15+AF15*2 -> 0
C16: T/S | AE16: =D16+F16+H16+J16+L16+N16+P16+R16+T16+V16+X16+Z16+AB16 -> 0 | AF16: =E16+G16+I16+K16+M16+O16+Q16+S16+U16+W16+Y16+AA16+AC16 -> 0 | AG16: =AE16+AF16*2 -> 0
C17: SOC | AE17: =D17+F17+H17+J17+L17+N17+P17+R17+T17+V17+X17+Z17+AB17 -> 0 | AF17: =E17+G17+I17+K17+M17+O17+Q17+S17+U17+W17+Y17+AA17+AC17 -> 0 | AG17: =AE17+AF17*2 -> 0
C18: RF | AE18: =D18+F18+H18+J18+L18+N18+P18+R18+T18+V18+X18+Z18+AB18 -> 0 | AF18: =E18+G18+I18+K18+M18+O18+Q18+S18+U18+W18+Y18+AA18+AC18 -> 0 | AG18: =AE18+AF18*2 -> 0 | AN18: =AN10-(AE18+AF18)+(D50+E50) -> 0
A19: ETB | B19: 07/22 | C19: MT | AE19: =D19+F19+H19+J19+L19+N19+P19+R19+T19+V19+X19+Z19+AB19 -> 0 | AF19: =E19+G19+I19+K19+M19+O19+Q19+S19+U19+W19+Y19+AA19+AC19 -> 0 | AG19: =AE19+AF19*2 -> 0
A20: ETD | B20: 07/24 | C20: Weight | AE20: =D20+F20+H20+J20+L20+N20+P20+R20+T20+V20+X20+Z20+AB20 -> 0 | AH20: =AH12+AE20-(D55) -> 0 | AI20: =AH20-(AH14-AI14)*2 -> 0 | AJ20: =IF($AJ$2>0,AH20/$AJ$2,0) -> 0 | AK20: =IF($AJ$2>0,AI20/$AJ$2,0) -> 0 | AM20: =$AJ$2-AH20 -> 0
C21: TTL | D21: =D14+D15+D16+D17+D18+D19 -> 0 | E21: =E14+E15+E16+E17+E18+E19 -> 0 | F21: =F14+F15+F16+F17+F18+F19 -> 0 | G21: =G14+G15+G16+G17+G18+G19 -> 0 | H21: =H14+H15+H16+H17+H18+H19 -> 0 | I21: =I14+I15+I16+I17+I18+I19 -> 0 | J21: =J14+J15+J16+J17+J18+J19 -> 0 | K21: =K14+K15+K16+K17+K18+K19 -> 0 | ... AC21: =AC14+AC15+AC16+AC17+AC18+AC19 -> 0 | AE21: =AE14+AE15+AE16+AE17+AE18+AE19 -> 0 | AF21: =AF14+AF15+AF16+AF17+AF18+AF19 -> 0 | AG21: =AG14+AG15+AG16+AG17+AG18+AG19 -> 0 | AL21: =$AG$2-AH14 -> 0
A22: OMSOH | C22: LILIAN | AE22: =D22+F22+H22+J22+L22+N22+P22+R22+T22+V22+X22+Z22+AB22 -> 0 | AF22: =E22+G22+I22+K22+M22+O22+Q22+S22+U22+W22+Y22+AA22+AC22 -> 0 | AG22: =AE22+AF22*2 -> 0 | AH22: =AH14+AG22+AG23+AG24+AG25+AG26+AG27-(F54) -> 0 | AI22: =AI14+AG22+AG23+AG24+AG25+AG26-((F54)-(F51+G51*2)) -> 0 | AJ22: =IF($AG$2>0,AH22/$AG$2,0) -> 0 | AK22: =IF($AG$2>0,AI22/$AG$2,0) -> 0
C23: SUL | AE23: =D23+F23+H23+J23+L23+N23+P23+R23+T23+V23+X23+Z23+AB23 -> 0 | AF23: =E23+G23+I23+K23+M23+O23+Q23+S23+U23+W23+Y23+AA23+AC23 -> 0 | AG23: =AE23+AF23*2 -> 0
C24: T/S | AE24: =D24+F24+H24+J24+L24+N24+P24+R24+T24+V24+X24+Z24+AB24 -> 0 | AF24: =E24+G24+I24+K24+M24+O24+Q24+S24+U24+W24+Y24+AA24+AC24 -> 0 | AG24: =AE24+AF24*2 -> 0
C25: SOC | AE25: =D25+F25+H25+J25+L25+N25+P25+R25+T25+V25+X25+Z25+AB25 -> 0 | AF25: =E25+G25+I25+K25+M25+O25+Q25+S25+U25+W25+Y25+AA25+AC25 -> 0 | AG25: =AE25+AF25*2 -> 0
C26: RF | AE26: =D26+F26+H26+J26+L26+N26+P26+R26+T26+V26+X26+Z26+AB26 -> 0 | AF26: =E26+G26+I26+K26+M26+O26+Q26+S26+U26+W26+Y26+AA26+AC26 -> 0 | AG26: =AE26+AF26*2 -> 0 | AN26: =AN18-(AE26+AF26)+(F50+G50) -> 0
A27: ETB | B27: 07/26 | C27: MT | AE27: =D27+F27+H27+J27+L27+N27+P27+R27+T27+V27+X27+Z27+AB27 -> 0 | AF27: =E27+G27+I27+K27+M27+O27+Q27+S27+U27+W27+Y27+AA27+AC27 -> 0 | AG27: =AE27+AF27*2 -> 0
A28: ETD | B28: 07/27 | C28: Weight | AE28: =D28+F28+H28+J28+L28+N28+P28+R28+T28+V28+X28+Z28+AB28 -> 0 | AH28: =AH20+AE28-(F55) -> 0 | AI28: =AH28-(AH22-AI22)*2 -> 0 | AJ28: =IF($AJ$2>0,AH28/$AJ$2,0) -> 0 | AK28: =IF($AJ$2>0,AI28/$AJ$2,0) -> 0 | AM28: =$AJ$2-AH28 -> 0
C29: TTL | D29: =D22+D23+D24+D25+D26+D27 -> 0 | E29: =E22+E23+E24+E25+E26+E27 -> 0 | F29: =F22+F23+F24+F25+F26+F27 -> 0 | G29: =G22+G23+G24+G25+G26+G27 -> 0 | H29: =H22+H23+H24+H25+H26+H27 -> 0 | I29: =I22+I23+I24+I25+I26+I27 -> 0 | J29: =J22+J23+J24+J25+J26+J27 -> 0 | K29: =K22+K23+K24+K25+K26+K27 -> 0 | ... AC29: =AC22+AC23+AC24+AC25+AC26+AC27 -> 0 | AE29: =AE22+AE23+AE24+AE25+AE26+AE27 -> 0 | AF29: =AF22+AF23+AF24+AF25+AF26+AF27 -> 0 | AG29: =AG22+AG23+AG24+AG25+AG26+AG27 -> 0 | AL29: =$AG$2-AH22 -> 0
A30: PKKHI | C30: LILIAN | AE30: =D30+F30+H30+J30+L30+N30+P30+R30+T30+V30+X30+Z30+AB30 -> 0 | AF30: =E30+G30+I30+K30+M30+O30+Q30+S30+U30+W30+Y30+AA30+AC30 -> 0 | AG30: =AE30+AF30*2 -> 0 | AH30: =AH22+AG30+AG31+AG32+AG33+AG34+AG35-(H54) -> 0 | AI30: =AI22+AG30+AG31+AG32+AG33+AG34-((H54)-(H51+I51*2)) -> 0 | AJ30: =IF($AG$2>0,AH30/$AG$2,0) -> 0 | AK30: =IF($AG$2>0,AI30/$AG$2,0) -> 0
C31: SUL | AE31: =D31+F31+H31+J31+L31+N31+P31+R31+T31+V31+X31+Z31+AB31 -> 0 | AF31: =E31+G31+I31+K31+M31+O31+Q31+S31+U31+W31+Y31+AA31+AC31 -> 0 | AG31: =AE31+AF31*2 -> 0
C32: T/S | AE32: =D32+F32+H32+J32+L32+N32+P32+R32+T32+V32+X32+Z32+AB32 -> 0 | AF32: =E32+G32+I32+K32+M32+O32+Q32+S32+U32+W32+Y32+AA32+AC32 -> 0 | AG32: =AE32+AF32*2 -> 0
C33: SOC | AE33: =D33+F33+H33+J33+L33+N33+P33+R33+T33+V33+X33+Z33+AB33 -> 0 | AF33: =E33+G33+I33+K33+M33+O33+Q33+S33+U33+W33+Y33+AA33+AC33 -> 0 | AG33: =AE33+AF33*2 -> 0
C34: RF | AE34: =D34+F34+H34+J34+L34+N34+P34+R34+T34+V34+X34+Z34+AB34 -> 0 | AF34: =E34+G34+I34+K34+M34+O34+Q34+S34+U34+W34+Y34+AA34+AC34 -> 0 | AG34: =AE34+AF34*2 -> 0 | AN34: =AN26-(AE34+AF34)+(H50+I50) -> 0
A35: ETB | B35: 07/30 | C35: MT | AE35: =D35+F35+H35+J35+L35+N35+P35+R35+T35+V35+X35+Z35+AB35 -> 0 | AF35: =E35+G35+I35+K35+M35+O35+Q35+S35+U35+W35+Y35+AA35+AC35 -> 0 | AG35: =AE35+AF35*2 -> 0
A36: ETD | B36: 08/01 | C36: Weight | AE36: =D36+F36+H36+J36+L36+N36+P36+R36+T36+V36+X36+Z36+AB36 -> 0 | AH36: =AH28+AE36-(H55) -> 0 | AI36: =AH36-(AH30-AI30)*2 -> 0 | AJ36: =IF($AJ$2>0,AH36/$AJ$2,0) -> 0 | AK36: =IF($AJ$2>0,AI36/$AJ$2,0) -> 0 | AM36: =$AJ$2-AH36 -> 0
C37: TTL | D37: =D30+D31+D32+D33+D34+D35 -> 0 | E37: =E30+E31+E32+E33+E34+E35 -> 0 | F37: =F30+F31+F32+F33+F34+F35 -> 0 | G37: =G30+G31+G32+G33+G34+G35 -> 0 | H37: =H30+H31+H32+H33+H34+H35 -> 0 | I37: =I30+I31+I32+I33+I34+I35 -> 0 | J37: =J30+J31+J32+J33+J34+J35 -> 0 | K37: =K30+K31+K32+K33+K34+K35 -> 0 | ... AC37: =AC30+AC31+AC32+AC33+AC34+AC35 -> 0 | AE37: =AE30+AE31+AE32+AE33+AE34+AE35 -> 0 | AF37: =AF30+AF31+AF32+AF33+AF34+AF35 -> 0 | AG37: =AG30+AG31+AG32+AG33+AG34+AG35 -> 0 | AL37: =$AG$2-AH30 -> 0
A38: CNTAO | C38: LILIAN | AE38: =D38+F38+H38+J38+L38+N38+P38+R38+T38+V38+X38+Z38+AB38 -> 0 | AF38: =E38+G38+I38+K38+M38+O38+Q38+S38+U38+W38+Y38+AA38+AC38 -> 0 | AG38: =AE38+AF38*2 -> 0 | AH38: =AH30+AG38+AG39+AG40+AG41+AG42+AG43-(J54) -> 0 | AI38: =AI30+AG38+AG39+AG40+AG41+AG42-((J54)-(J51+K51*2)) -> 0 | AJ38: =IF($AG$2>0,AH38/$AG$2,0) -> 0 | AK38: =IF($AG$2>0,AI38/$AG$2,0) -> 0
C39: SUL | AE39: =D39+F39+H39+J39+L39+N39+P39+R39+T39+V39+X39+Z39+AB39 -> 0 | AF39: =E39+G39+I39+K39+M39+O39+Q39+S39+U39+W39+Y39+AA39+AC39 -> 0 | AG39: =AE39+AF39*2 -> 0
C40: T/S | AE40: =D40+F40+H40+J40+L40+N40+P40+R40+T40+V40+X40+Z40+AB40 -> 0 | AF40: =E40+G40+I40+K40+M40+O40+Q40+S40+U40+W40+Y40+AA40+AC40 -> 0 | AG40: =AE40+AF40*2 -> 0
...
